Workbook

Sheet Inputs 2026
A1: Row | B1: First | C1: Second | D1: Third | E1: Note
A2: Line 2 | B2: 2.675 | D2: -1
A3: Line 3 | B3: 0 | C3: 1234.5678 | D3: 1
A4: Line 4 | B4: 1.005 | C4: 10 | E4: checked
A5: Line 5 | B5: -294 | C5: 100 | E5: -19.99
A6: Line 6 | C6: 0.25 | E6: 2.675
A7: Line 7 | B7: 3 | C7: 0.1 | D7: -1
A8: Line 8 | C8: -19.99 | D8: 1 | E8: checked
A9: Line 9 | B9: 0.5 | C9: 10 | D9: -4 | E9: n/a
A10: Line 10 | B10: -4 | C10: -1 | D10: 1
A11: Line 11 | B11: 10 | C11: 0.2 | D11: 7
A12: Line 12 | B12: 100 | C12: 25 | D12: 0.1
A13: Line 13 | B13: 7 | C13: 381 | D13: 0.1
A14: Line 14 | B14: 0.25 | C14: 10 | D14: 924.48 | E14: checked
A15: Line 15 | B15: 0.25
A16: Line 16 | B16: -4 | C16: 1.005 | D16: 1 | E16: 0.25
A17: Line 17 | B17: -19.99 | C17: -4 | D17: 100
A18: Line 18 | B18: 10 | C18: 1 | D18: 1234.5678 | E18: 0.25
A19: Line 19 | B19: 2.675 | C19: -1 | D19: 0 | E19: checked
A20: Line 20 | B20: -4 | C20: 100 | D20: 25
A21: Line 21 | B21: 1 | C21: -19.99 | D21: 100
A22: Line 22 | B22: 0 | C22: 25 | D22: 0 | E22: 2.675
A23: Line 23 | C23: 0.2 | D23: 25 | E23: n/a
A24: Line 24 | B24: 21 | C24: 0 | D24: 0.1 | E24: 0
A25: Line 25 | C25: 0.2 | D25: 1 | E25: 2
A26: Line 26 | B26: 0.2 | C26: 2.675 | D26: 7
A27: Line 27 | B27: 100 | C27: 0.25 | D27: -4 | E27: 0
A28: Line 28 | B28: 0.25 | C28: 0.5 | D28: 1234.5678 | E28: n/a
A29: Line 29 | B29: 25 | C29: -1 | D29: 3
A30: Line 30 | B30: -1 | C30: 2 | D30: 0.1 | E30: checked
A31: Line 31 | B31: 0.5 | C31: 10 | D31: 3 | E31: 7
A32: Line 32 | B32: 1 | C32: 1.005 | D32: 0.1 | E32: n/a
A33: Line 33 | B33: 100 | C33: 617.06 | D33: 0
A34: Line 34 | B34: 1.005 | C34: -601.16 | D34: 0.2 | E34: checked
A35: Line 35 | B35: 10 | C35: 100 | D35: 32
A36: Line 36 | B36: 1.005 | C36: -19.99 | E36: 100
A37: Line 37 | B37: 296 | C37: -488 | D37: 0.2
A38: Line 38 | B38: 25 | C38: -19.99 | D38: -1 | E38: n/a
A39: Line 39 | B39: 3 | C39: 25 | D39: 0.1 | E39: n/a
A40: Line 40 | B40: -1 | C40: 0 | D40: 2.675 | E40: 0.2
...

Sheet Formulas
A1: Row | B1: Formula 1 | C1: Formula 2 | D1: Formula 3 | E1: Formula 4 | F1: Formula 5 | G1: Formula 6 | H1: Formula 7 | I1: Formula 8 | J1: Formula 9 | K1: Formula 10 | L1: Formula 11 | M1: Formula 12 | N1: Formula 13 | O1: Formula 14 | P1: Formula 15 | Q1: Formula 16 | R1: Formula 17 | S1: Formula 18 | T1: Formula 19 | U1: Formula 20 | V1: Formula 21 | W1: Formula 22 | X1: Formula 23 | Y1: Formula 24
A2: Line 2 | B2: ='Inputs 2026'!B2+'Inputs 2026'!C2*'Inputs 2026'!D2 -> 2.675 | C2: =('Inputs 2026'!B2-'Inputs 2026'!C2)/'Inputs 2026'!D2 -> -2.675 | D2: =SUM('Inputs 2026'!B2:D2) -> 1.675 | E2: =AVERAGE('Inputs 2026'!B2:E2) -> 0.8375 | F2: =MIN('Inputs 2026'!B2:E2) -> -1 | G2: =MAX('Inputs 2026'!B2:E2) -> 2.675 | H2: =COUNT('Inputs 2026'!B2:E2) -> 2 | I2: =ROUND('Inputs 2026'!B2/7,2) -> 0.38 | J2: =ROUND('Inputs 2026'!C2*1.005,2) -> 0 | K2: =ROUND('Inputs 2026'!D2*1234.5678,-2) -> -1200 | L2: =IF('Inputs 2026'!B2>'Inputs 2026'!C2,'Inputs 2026'!B2,'Inputs 2026'!C2*2) -> 2.675 | M2: =IF('Inputs 2026'!B2='Inputs 2026'!C2,1,0) -> 0 | N2: =IF('Inputs 2026'!D2<>0,'Inputs 2026'!B2/'Inputs 2026'!D2,0) -> -2.675 | O2: =-'Inputs 2026'!B2%*50% -> -0.013375 | P2: =C2*2+D2 -> -3.675 | Q2: =SUM($C$2:C2) -> -2.675 | R2: =$D$2+P2 -> -2 | S2: =COUNT(B2:Q2) -> 16 | T2: =IF('Inputs 2026'!E2>5,1,0) -> 0 | U2: =IF('Inputs 2026'!E2='Inputs 2026'!D2,1,0) -> 0 | V2: =IF('Inputs 2026'!E2,1,2) -> 2 | W2: =IF('Inputs 2026'!B2>0,IF('Inputs 2026'!C2>0,1,2),3) -> 2 | X2: =SUM('Inputs 2026'!E2,'Inputs 2026'!B2,5) -> 7.675 | Y2: =MAX('Inputs 2026'!B2:C2,10)-MIN('Inputs 2026'!D2,'Inputs 2026'!E2) -> 11
A3: Line 3 | B3: ='Inputs 2026'!B3+'Inputs 2026'!C3*'Inputs 2026'!D3 -> 1234.5678 | C3: =('Inputs 2026'!B3-'Inputs 2026'!C3)/'Inputs 2026'!D3 -> -1234.5678 | D3: =SUM('Inputs 2026'!B3:D3) -> 1235.5678 | E3: =AVERAGE('Inputs 2026'!B3:E3) -> 411.85593 | F3: =MIN('Inputs 2026'!B3:E3) -> 0 | G3: =MAX('Inputs 2026'!B3:E3) -> 1234.5678 | H3: =COUNT('Inputs 2026'!B3:E3) -> 3 | I3: =ROUND('Inputs 2026'!B3/7,2) -> 0 | J3: =ROUND('Inputs 2026'!C3*1.005,2) -> 1240.74 | K3: =ROUND('Inputs 2026'!D3*1234.5678,-2) -> 1200 | L3: =IF('Inputs 2026'!B3>'Inputs 2026'!C3,'Inputs 2026'!B3,'Inputs 2026'!C3*2) -> 2469.1356 | M3: =IF('Inputs 2026'!B3='Inputs 2026'!C3,1,0) -> 0 | N3: =IF('Inputs 2026'!D3<>0,'Inputs 2026'!B3/'Inputs 2026'!D3,0) -> 0 | O3: =-'Inputs 2026'!B3%*50% -> 0 | P3: =C3*2+D3 -> -1233.5678 | Q3: =SUM($C$2:C3) -> -1237.2428 | R3: =$D$2+P3 -> -1231.8928 | S3: =COUNT(B3:Q3) -> 16 | T3: =IF('Inputs 2026'!E3>5,1,0) -> 0 | U3: =IF('Inputs 2026'!E3='Inputs 2026'!D3,1,0) -> 0 | V3: =IF('Inputs 2026'!E3,1,2) -> 2 | W3: =IF('Inputs 2026'!B3>0,IF('Inputs 2026'!C3>0,1,2),3) -> 3 | X3: =SUM('Inputs 2026'!E3,'Inputs 2026'!B3,5) -> 5 | Y3: =MAX('Inputs 2026'!B3:C3,10)-MIN('Inputs 2026'!D3,'Inputs 2026'!E3) -> 1233.5678
A4: Line 4 | B4: ='Inputs 2026'!B4+'Inputs 2026'!C4*'Inputs 2026'!D4 -> 1.005 | C4: =('Inputs 2026'!B4-'Inputs 2026'!C4)/'Inputs 2026'!D4 -> #DIV/0! | D4: =SUM('Inputs 2026'!B4:D4) -> 11.005 | E4: =AVERAGE('Inputs 2026'!B4:E4) -> 5.5025 | F4: =MIN('Inputs 2026'!B4:E4) -> 1.005 | G4: =MAX('Inputs 2026'!B4:E4) -> 10 | H4: =COUNT('Inputs 2026'!B4:E4) -> 2 | I4: =ROUND('Inputs 2026'!B4/7,2) -> 0.14 | J4: =ROUND('Inputs 2026'!C4*1.005,2) -> 10.05 | K4: =ROUND('Inputs 2026'!D4*1234.5678,-2) -> 0 | L4: =IF('Inputs 2026'!B4>'Inputs 2026'!C4,'Inputs 2026'!B4,'Inputs 2026'!C4*2) -> 20 | M4: =IF('Inputs 2026'!B4='Inputs 2026'!C4,1,0) -> 0 | N4: =IF('Inputs 2026'!D4<>0,'Inputs 2026'!B4/'Inputs 2026'!D4,0) -> 0 | O4: =-'Inputs 2026'!B4%*50% -> -0.005025 | P4: =C4*2+D4 -> #DIV/0! | Q4: =SUM($C$2:C4) -> #DIV/0! | R4: =$D$2+P4 -> #DIV/0! | S4: =COUNT(B4:Q4) -> 13 | T4: =IF('Inputs 2026'!E4>5,1,0) -> 1 | U4: =IF('Inputs 2026'!E4='Inputs 2026'!D4,1,0) -> 0 | V4: =IF('Inputs 2026'!E4,1,2) -> #VALUE! | W4: =IF('Inputs 2026'!B4>0,IF('Inputs 2026'!C4>0,1,2),3) -> 1 | X4: =SUM('Inputs 2026'!E4,'Inputs 2026'!B4,5) -> 6.005 | Y4: =MAX('Inputs 2026'!B4:C4,10)-MIN('Inputs 2026'!D4,'Inputs 2026'!E4) -> 10
A5: Line 5 | B5: ='Inputs 2026'!B5+'Inputs 2026'!C5*'Inputs 2026'!D5 -> -294 | C5: =('Inputs 2026'!B5-'Inputs 2026'!C5)/'Inputs 2026'!D5 -> #DIV/0! | D5: =SUM('Inputs 2026'!B5:D5) -> -194 | E5: =AVERAGE('Inputs 2026'!B5:E5) -> -71.33 | F5: =MIN('Inputs 2026'!B5:E5) -> -294 | G5: =MAX('Inputs 2026'!B5:E5) -> 100 | H5: =COUNT('Inputs 2026'!B5:E5) -> 3 | I5: =ROUND('Inputs 2026'!B5/7,2) -> -42 | J5: =ROUND('Inputs 2026'!C5*1.005,2) -> 100.5 | K5: =ROUND('Inputs 2026'!D5*1234.5678,-2) -> 0 | L5: =IF('Inputs 2026'!B5>'Inputs 2026'!C5,'Inputs 2026'!B5,'Inputs 2026'!C5*2) -> 200 | M5: =IF('Inputs 2026'!B5='Inputs 2026'!C5,1,0) -> 0 | N5: =IF('Inputs 2026'!D5<>0,'Inputs 2026'!B5/'Inputs 2026'!D5,0) -> 0 | O5: =-'Inputs 2026'!B5%*50% -> 1.47 | P5: =C5*2+D5 -> #DIV/0! | Q5: =SUM($C$2:C5) -> #DIV/0! | R5: =$D$2+P5 -> #DIV/0! | S5: =COUNT(B5:Q5) -> 13 | T5: =IF('Inputs 2026'!E5>5,1,0) -> 0 | U5: =IF('Inputs 2026'!E5='Inputs 2026'!D5,1,0) -> 0 | V5: =IF('Inputs 2026'!E5,1,2) -> 1 | W5: =IF('Inputs 2026'!B5>0,IF('Inputs 2026'!C5>0,1,2),3) -> 3 | X5: =SUM('Inputs 2026'!E5,'Inputs 2026'!B5,5) -> -308.99 | Y5: =MAX('Inputs 2026'!B5:C5,10)-MIN('Inputs 2026'!D5,'Inputs 2026'!E5) -> 119.99
A6: Line 6 | B6: ='Inputs 2026'!B6+'Inputs 2026'!C6*'Inputs 2026'!D6 -> 0 | C6: =('Inputs 2026'!B6-'Inputs 2026'!C6)/'Inputs 2026'!D6 -> #DIV/0! | D6: =SUM('Inputs 2026'!B6:D6) -> 0.25 | E6: =AVERAGE('Inputs 2026'!B6:E6) -> 1.4625 | F6: =MIN('Inputs 2026'!B6:E6) -> 0.25 | G6: =MAX('Inputs 2026'!B6:E6) -> 2.675 | H6: =COUNT('Inputs 2026'!B6:E6) -> 2 | I6: =ROUND('Inputs 2026'!B6/7,2) -> 0 | J6: =ROUND('Inputs 2026'!C6*1.005,2) -> 0.25 | K6: =ROUND('Inputs 2026'!D6*1234.5678,-2) -> 0 | L6: =IF('Inputs 2026'!B6>'Inputs 2026'!C6,'Inputs 2026'!B6,'Inputs 2026'!C6*2) -> 0.5 | M6: =IF('Inputs 2026'!B6='Inputs 2026'!C6,1,0) -> 0 | N6: =IF('Inputs 2026'!D6<>0,'Inputs 2026'!B6/'Inputs 2026'!D6,0) -> 0 | O6: =-'Inputs 2026'!B6%*50% -> 0 | P6: =C6*2+D6 -> #DIV/0! | Q6: =SUM($C$2:C6) -> #DIV/0! | R6: =$D$2+P6 -> #DIV/0! | S6: =COUNT(B6:Q6) -> 13 | T6: =IF('Inputs 2026'!E6>5,1,0) -> 0 | U6: =IF('Inputs 2026'!E6='Inputs 2026'!D6,1,0) -> 0 | V6: =IF('Inputs 2026'!E6,1,2) -> 1 | W6: =IF('Inputs 2026'!B6>0,IF('Inputs 2026'!C6>0,1,2),3) -> 3 | X6: =SUM('Inputs 2026'!E6,'Inputs 2026'!B6,5) -> 7.675 | Y6: =MAX('Inputs 2026'!B6:C6,10)-MIN('Inputs 2026'!D6,'Inputs 2026'!E6) -> 7.325
A7: Line 7 | B7: ='Inputs 2026'!B7+'Inputs 2026'!C7*'Inputs 2026'!D7 -> 2.9 | C7: =('Inputs 2026'!B7-'Inputs 2026'!C7)/'Inputs 2026'!D7 -> -2.9 | D7: =SUM('Inputs 2026'!B7:D7) -> 2.1 | E7: =AVERAGE('Inputs 2026'!B7:E7) -> 0.7 | F7: =MIN('Inputs 2026'!B7:E7) -> -1 | G7: =MAX('Inputs 2026'!B7:E7) -> 3 | H7: =COUNT('Inputs 2026'!B7:E7) -> 3 | I7: =ROUND('Inputs 2026'!B7/7,2) -> 0.43 | J7: =ROUND('Inputs 2026'!C7*1.005,2) -> 0.1 | K7: =ROUND('Inputs 2026'!D7*1234.5678,-2) -> -1200 | L7: =IF('Inputs 2026'!B7>'Inputs 2026'!C7,'Inputs 2026'!B7,'Inputs 2026'!C7*2) -> 3 | M7: =IF('Inputs 2026'!B7='Inputs 2026'!C7,1,0) -> 0 | N7: =IF('Inputs 2026'!D7<>0,'Inputs 2026'!B7/'Inputs 2026'!D7,0) -> -3 | O7: =-'Inputs 2026'!B7%*50% -> -0.015 | P7: =C7*2+D7 -> -3.7 | Q7: =SUM($C$2:C7) -> #DIV/0! | R7: =$D$2+P7 -> -2.025 | S7: =COUNT(B7:Q7) -> 15 | T7: =IF('Inputs 2026'!E7>5,1,0) -> 0 | U7: =IF('Inputs 2026'!E7='Inputs 2026'!D7,1,0) -> 0 | V7: =IF('Inputs 2026'!E7,1,2) -> 2 | W7: =IF('Inputs 2026'!B7>0,IF('Inputs 2026'!C7>0,1,2),3) -> 1 | X7: =SUM('Inputs 2026'!E7,'Inputs 2026'!B7,5) -> 8 | Y7: =MAX('Inputs 2026'!B7:C7,10)-MIN('Inputs 2026'!D7,'Inputs 2026'!E7) -> 11
A8: Line 8 | B8: ='Inputs 2026'!B8+'Inputs 2026'!C8*'Inputs 2026'!D8 -> -19.99 | C8: =('Inputs 2026'!B8-'Inputs 2026'!C8)/'Inputs 2026'!D8 -> 19.99 | D8: =SUM('Inputs 2026'!B8:D8) -> -18.99 | E8: =AVERAGE('Inputs 2026'!B8:E8) -> -9.495 | F8: =MIN('Inputs 2026'!B8:E8) -> -19.99 | G8: =MAX('Inputs 2026'!B8:E8) -> 1 | H8: =COUNT('Inputs 2026'!B8:E8) -> 2 | I8: =ROUND('Inputs 2026'!B8/7,2) -> 0 | J8: =ROUND('Inputs 2026'!C8*1.005,2) -> -20.09 | K8: =ROUND('Inputs 2026'!D8*1234.5678,-2) -> 1200 | L8: =IF('Inputs 2026'!B8>'Inputs 2026'!C8,'Inputs 2026'!B8,'Inputs 2026'!C8*2) -> 0 | M8: =IF('Inputs 2026'!B8='Inputs 2026'!C8,1,0) -> 0 | N8: =IF('Inputs 2026'!D8<>0,'Inputs 2026'!B8/'Inputs 2026'!D8,0) -> 0 | O8: =-'Inputs 2026'!B8%*50% -> 0 | P8: =C8*2+D8 -> 20.99 | Q8: =SUM($C$2:C8) -> #DIV/0! | R8: =$D$2+P8 -> 22.665 | S8: =COUNT(B8:Q8) -> 15 | T8: =IF('Inputs 2026'!E8>5,1,0) -> 1 | U8: =IF('Inputs 2026'!E8='Inputs 2026'!D8,1,0) -> 0 | V8: =IF('Inputs 2026'!E8,1,2) -> #VALUE! | W8: =IF('Inputs 2026'!B8>0,IF('Inputs 2026'!C8>0,1,2),3) -> 3 | X8: =SUM('Inputs 2026'!E8,'Inputs 2026'!B8,5) -> 5 | Y8: =MAX('Inputs 2026'!B8:C8,10)-MIN('Inputs 2026'!D8,'Inputs 2026'!E8) -> 9
A9: Line 9 | B9: ='Inputs 2026'!B9+'Inputs 2026'!C9*'Inputs 2026'!D9 -> -39.5 | C9: =('Inputs 2026'!B9-'Inputs 2026'!C9)/'Inputs 2026'!D9 -> 2.375 | D9: =SUM('Inputs 2026'!B9:D9) -> 6.5 | E9: =AVERAGE('Inputs 2026'!B9:E9) -> 2.1666667 | F9: =MIN('Inputs 2026'!B9:E9) -> -4 | G9: =MAX('Inputs 2026'!B9:E9) -> 10 | H9: =COUNT('Inputs 2026'!B9:E9) -> 3 | I9: =ROUND('Inputs 2026'!B9/7,2) -> 0.07 | J9: =ROUND('Inputs 2026'!C9*1.005,2) -> 10.05 | K9: =ROUND('Inputs 2026'!D9*1234.5678,-2) -> -4900 | L9: =IF('Inputs 2026'!B9>'Inputs 2026'!C9,'Inputs 2026'!B9,'Inputs 2026'!C9*2) -> 20 | M9: =IF('Inputs 2026'!B9='Inputs 2026'!C9,1,0) -> 0 | N9: =IF('Inputs 2026'!D9<>0,'Inputs 2026'!B9/'Inputs 2026'!D9,0) -> -0.125 | O9: =-'Inputs 2026'!B9%*50% -> -0.0025 | P9: =C9*2+D9 -> 11.25 | Q9: =SUM($C$2:C9) -> #DIV/0! | R9: =$D$2+P9 -> 12.925 | S9: =COUNT(B9:Q9) -> 15 | T9: =IF('Inputs 2026'!E9>5,1,0) -> 1 | U9: =IF('Inputs 2026'!E9='Inputs 2026'!D9,1,0) -> 0 | V9: =IF('Inputs 2026'!E9,1,2) -> #VALUE! | W9: =IF('Inputs 2026'!B9>0,IF('Inputs 2026'!C9>0,1,2),3) -> 1 | X9: =SUM('Inputs 2026'!E9,'Inputs 2026'!B9,5) -> 5.5 | Y9: =MAX('Inputs 2026'!B9:C9,10)-MIN('Inputs 2026'!D9,'Inputs 2026'!E9) -> 14
A10: Line 10 | B10: ='Inputs 2026'!B10+'Inputs 2026'!C10*'Inputs 2026'!D10 -> -5 | C10: =('Inputs 2026'!B10-'Inputs 2026'!C10)/'Inputs 2026'!D10 -> -3 | D10: =SUM('Inputs 2026'!B10:D10) -> -4 | E10: =AVERAGE('Inputs 2026'!B10:E10) -> -1.3333333 | F10: =MIN('Inputs 2026'!B10:E10) -> -4 | G10: =MAX('Inputs 2026'!B10:E10) -> 1 | H10: =COUNT('Inputs 2026'!B10:E10) -> 3 | I10: =ROUND('Inputs 2026'!B10/7,2) -> -0.57 | J10: =ROUND('Inputs 2026'!C10*1.005,2) -> -1.01 | K10: =ROUND('Inputs 2026'!D10*1234.5678,-2) -> 1200 | L10: =IF('Inputs 2026'!B10>'Inputs 2026'!C10,'Inputs 2026'!B10,'Inputs 2026'!C10*2) -> -2 | M10: =IF('Inputs 2026'!B10='Inputs 2026'!C10,1,0) -> 0 | N10: =IF('Inputs 2026'!D10<>0,'Inputs 2026'!B10/'Inputs 2026'!D10,0) -> -4 | O10: =-'Inputs 2026'!B10%*50% -> 0.02 | P10: =C10*2+D10 -> -10 | Q10: =SUM($C$2:C10) -> #DIV/0! | R10: =$D$2+P10 -> -8.325 | S10: =COUNT(B10:Q10) -> 15 | T10: =IF('Inputs 2026'!E10>5,1,0) -> 0 | U10: =IF('Inputs 2026'!E10='Inputs 2026'!D10,1,0) -> 0 | V10: =IF('Inputs 2026'!E10,1,2) -> 2 | W10: =IF('Inputs 2026'!B10>0,IF('Inputs 2026'!C10>0,1,2),3) -> 3 | X10: =SUM('Inputs 2026'!E10,'Inputs 2026'!B10,5) -> 1 | Y10: =MAX('Inputs 2026'!B10:C10,10)-MIN('Inputs 2026'!D10,'Inputs 2026'!E10) -> 9
A11: Line 11 | B11: ='Inputs 2026'!B11+'Inputs 2026'!C11*'Inputs 2026'!D11 -> 11.4 | C11: =('Inputs 2026'!B11-'Inputs 2026'!C11)/'Inputs 2026'!D11 -> 1.4 | D11: =SUM('Inputs 2026'!B11:D11) -> 17.2 | E11: =AVERAGE('Inputs 2026'!B11:E11) -> 5.7333333 | F11: =MIN('Inputs 2026'!B11:E11) -> 0.2 | G11: =MAX('Inputs 2026'!B11:E11) -> 10 | H11: =COUNT('Inputs 2026'!B11:E11) -> 3 | I11: =ROUND('Inputs 2026'!B11/7,2) -> 1.43 | J11: =ROUND('Inputs 2026'!C11*1.005,2) -> 0.2 | K11: =ROUND('Inputs 2026'!D11*1234.5678,-2) -> 8600 | L11: =IF('Inputs 2026'!B11>'Inputs 2026'!C11,'Inputs 2026'!B11,'Inputs 2026'!C11*2) -> 10 | M11: =IF('Inputs 2026'!B11='Inputs 2026'!C11,1,0) -> 0 | N11: =IF('Inputs 2026'!D11<>0,'Inputs 2026'!B11/'Inputs 2026'!D11,0) -> 1.4285714 | O11: =-'Inputs 2026'!B11%*50% -> -0.05 | P11: =C11*2+D11 -> 20 | Q11: =SUM($C$2:C11) -> #DIV/0! | R11: =$D$2+P11 -> 21.675 | S11: =COUNT(B11:Q11) -> 15 | T11: =IF('Inputs 2026'!E11>5,1,0) -> 0 | U11: =IF('Inputs 2026'!E11='Inputs 2026'!D11,1,0) -> 0 | V11: =IF('Inputs 2026'!E11,1,2) -> 2 | W11: =IF('Inputs 2026'!B11>0,IF('Inputs 2026'!C11>0,1,2),3) -> 1 | X11: =SUM('Inputs 2026'!E11,'Inputs 2026'!B11,5) -> 15 | Y11: =MAX('Inputs 2026'!B11:C11,10)-MIN('Inputs 2026'!D11,'Inputs 2026'!E11) -> 3
A12: Line 12 | B12: ='Inputs 2026'!B12+'Inputs 2026'!C12*'Inputs 2026'!D12 -> 102.5 | C12: =('Inputs 2026'!B12-'Inputs 2026'!C12)/'Inputs 2026'!D12 -> 750 | D12: =SUM('Inputs 2026'!B12:D12) -> 125.1 | E12: =AVERAGE('Inputs 2026'!B12:E12) -> 41.7 | F12: =MIN('Inputs 2026'!B12:E12) -> 0.1 | G12: =MAX('Inputs 2026'!B12:E12) -> 100 | H12: =COUNT('Inputs 2026'!B12:E12) -> 3 | I12: =ROUND('Inputs 2026'!B12/7,2) -> 14.29 | J12: =ROUND('Inputs 2026'!C12*1.005,2) -> 25.13 | K12: =ROUND('Inputs 2026'!D12*1234.5678,-2) -> 100 | L12: =IF('Inputs 2026'!B12>'Inputs 2026'!C12,'Inputs 2026'!B12,'Inputs 2026'!C12*2) -> 100 | M12: =IF('Inputs 2026'!B12='Inputs 2026'!C12,1,0) -> 0 | N12: =IF('Inputs 2026'!D12<>0,'Inputs 2026'!B12/'Inputs 2026'!D12,0) -> 1000 | O12: =-'Inputs 2026'!B12%*50% -> -0.5 | P12: =C12*2+D12 -> 1625.1 | Q12: =SUM($C$2:C12) -> #DIV/0! | R12: =$D$2+P12 -> 1626.775 | S12: =COUNT(B12:Q12) -> 15 | T12: =IF('Inputs 2026'!E12>5,1,0) -> 0 | U12: =IF('Inputs 2026'!E12='Inputs 2026'!D12,1,0) -> 0 | V12: =IF('Inputs 2026'!E12,1,2) -> 2 | W12: =IF('Inputs 2026'!B12>0,IF('Inputs 2026'!C12>0,1,2),3) -> 1 | X12: =SUM('Inputs 2026'!E12,'Inputs 2026'!B12,5) -> 105 | Y12: =MAX('Inputs 2026'!B12:C12,10)-MIN('Inputs 2026'!D12,'Inputs 2026'!E12) -> 99.9
A13: Line 13 | B13: ='Inputs 2026'!B13+'Inputs 2026'!C13*'Inputs 2026'!D13 -> 45.1 | C13: =('Inputs 2026'!B13-'Inputs 2026'!C13)/'Inputs 2026'!D13 -> -3740 | D13: =SUM('Inputs 2026'!B13:D13) -> 388.1 | E13: =AVERAGE('Inputs 2026'!B13:E13) -> 129.36667 | F13: =MIN('Inputs 2026'!B13:E13) -> 0.1 | G13: =MAX('Inputs 2026'!B13:E13) -> 381 | H13: =COUNT('Inputs 2026'!B13:E13) -> 3 | I13: =ROUND('Inputs 2026'!B13/7,2) -> 1 | J13: =ROUND('Inputs 2026'!C13*1.005,2) -> 382.91 | K13: =ROUND('Inputs 2026'!D13*1234.5678,-2) -> 100 | L13: =IF('Inputs 2026'!B13>'Inputs 2026'!C13,'Inputs 2026'!B13,'Inputs 2026'!C13*2) -> 762 | M13: =IF('Inputs 2026'!B13='Inputs 2026'!C13,1,0) -> 0 | N13: =IF('Inputs 2026'!D13<>0,'Inputs 2026'!B13/'Inputs 2026'!D13,0) -> 70 | O13: =-'Inputs 2026'!B13%*50% -> -0.035 | P13: =C13*2+D13 -> -7091.9 | Q13: =SUM($C$2:C13) -> #DIV/0! | R13: =$D$2+P13 -> -7090.225 | S13: =COUNT(B13:Q13) -> 15 | T13: =IF('Inputs 2026'!E13>5,1,0) -> 0 | U13: =IF('Inputs 2026'!E13='Inputs 2026'!D13,1,0) -> 0 | V13: =IF('Inputs 2026'!E13,1,2) -> 2 | W13: =IF('Inputs 2026'!B13>0,IF('Inputs 2026'!C13>0,1,2),3) -> 1 | X13: =SUM('Inputs 2026'!E13,'Inputs 2026'!B13,5) -> 12 | Y13: =MAX('Inputs 2026'!B13:C13,10)-MIN('Inputs 2026'!D13,'Inputs 2026'!E13) -> 380.9
... A151: Line 151 | B151: ='Inputs 2026'!B151+'Inputs 2026'!C151*'Inputs 2026'!D151 -> -1164.93 | C151: =('Inputs 2026'!B151-'Inputs 2026'!C151)/'Inputs 2026'!D151 -> 216.2325 | D151: =SUM('Inputs 2026'!B151:D151) -> -668.93 | E151: =AVERAGE('Inputs 2026'!B151:E151) -> -222.97667 | F151: =MIN('Inputs 2026'!B151:E151) -> -764.93 | G151: =MAX('Inputs 2026'!B151:E151) -> 100 | H151: =COUNT('Inputs 2026'!B151:E151) -> 3 | I151: =ROUND('Inputs 2026'!B151/7,2) -> -109.28 | J151: =ROUND('Inputs 2026'!C151*1.005,2) -> 100.5 | K151: =ROUND('Inputs 2026'!D151*1234.5678,-2) -> -4900 | L151: =IF('Inputs 2026'!B151>'Inputs 2026'!C151,'Inputs 2026'!B151,'Inputs 2026'!C151*2) -> 200 | M151: =IF('Inputs 2026'!B151='Inputs 2026'!C151,1,0) -> 0 | N151: =IF('Inputs 2026'!D151<>0,'Inputs 2026'!B151/'Inputs 2026'!D151,0) -> 191.2325 | O151: =-'Inputs 2026'!B151%*50% -> 3.82465 | P151: =C151*2+D151 -> -236.465 | Q151: =SUM($C$2:C151) -> #DIV/0! | R151: =$D$2+P151 -> -234.79 | S151: =COUNT(B151:Q151) -> 15 | T151: =IF('Inputs 2026'!E151>5,1,0) -> 1 | U151: =IF('Inputs 2026'!E151='Inputs 2026'!D151,1,0) -> 0 | V151: =IF('Inputs 2026'!E151,1,2) -> #VALUE! | W151: =IF('Inputs 2026'!B151>0,IF('Inputs 2026'!C151>0,1,2),3) -> 3 | X151: =SUM('Inputs 2026'!E151,'Inputs 2026'!B151,5) -> -759.93 | Y151: =MAX('Inputs 2026'!B151:C151,10)-MIN('Inputs 2026'!D151,'Inputs 2026'!E151) -> 104
